Workbook
Name NativeTimeline_Order_Date: #N/A
Name Slicer_Loyalty_Card: #N/A
Name Slicer_Roast_Type_Name: #N/A
Name Slicer_Size: #N/A

Sheet Coffee Sales Dashboard

Sheet Total Sales
A3: Sum of Sales | C3: CoffeeType Name
A4: Years (Order Date) | B4: Months (Order Date) | C4: Arabica | D4: Excelsa | E4: Liberica | F4: Robusta
A5: 2019 | B5: Jan | C5: 68.655 | D5: 111.78 | E5: 36.455
B6: Feb | C6: 148.925 | E6: 271.745 | F6: 41.17
B7: Mar | C7: 137.195 | D7: 230.92 | E7: 133.86
B8: Apr | C8: 155.25 | D8: 512.325 | E8: 316.135 | F8: 54.97
B9: May | C9: 29.785 | E9: 145.82
B10: Jun | C10: 155.25 | D10: 626.175 | E10: 89.355 | F10: 219.765
B11: Jul | C11: 272.435 | D11: 204.93 | F11: 123.51
B12: Aug | C12: 226.55 | F12: 68.655
B13: Sep | C13: 178.71 | E13: 273.7 | F13: 361.56
B14: Oct | C14: 100.51 | D14: 96.255 | E14: 109.365
B15: Nov | C15: 178.71 | D15: 63.25 | E15: 272.32
B16: Dec | C16: 155.25 | D16: 444.015 | F16: 130.525
A17: 2020 | B17: Jan | E17: 189.06 | F17: 27.485
B18: Feb | C18: 678.385 | D18: 227.24 | E18: 89.355 | F18: 357.305
B19: Mar | D19: 62.1 | E19: 148.925 | F19: 137.31
B20: Apr | D20: 253 | E20: 33.465 | F20: 196.765
B21: May | C21: 77.625 | D21: 472.88 | E21: 33.465 | F21: 41.17
B22: Jun | C22: 473.34 | D22: 165.715 | E22: 192.05 | F22: 132.825
B23: Jul | C23: 297.85 | D23: 31.625 | E23: 36.455 | F23: 247.02
B24: Aug | F24: 41.17
B25: Sep | C25: 91.54 | F25: 155.71
B26: Oct | C26: 198.03 | D26: 254.61 | E26: 238.28 | F26: 109.94
B27: Nov | C27: 476.33 | D27: 111.78 | E27: 228.505 | F27: 27.485
B28: Dec | D28: 171.35 | F28: 45.77
A29: 2021 | B29: Jan | C29: 77.625 | D29: 31.625 | E29: 29.785 | F29: 91.54
B30: Feb | C30: 217.925 | D30: 139.725 | E30: 139.84
B31: Mar | C31: 268.065 | D31: 194.81 | E31: 228.505
B32: Apr | D32: 147.085 | E32: 401.005 | F32: 82.34
B33: May | C33: 103.5 | E33: 148.925 | F33: 192.395
B34: Jun | C34: 240.81 | E34: 148.925 | F34: 61.755
B35: Jul | D35: 189.75 | F35: 109.94
B36: Aug | C36: 141.105 | D36: 111.78 | F36: 196.765
B37: Sep | C37: 629.28 | D37: 83.835 | F37: 109.94
B38: Oct | C38: 166.175 | D38: 187.45 | E38: 251.62 | F38: 91.54
B39: Nov | C39: 137.31 | D39: 297.85 | E39: 119.14 | F39: 68.655
B40: Dec | C40: 178.71 | E40: 212.75 | F40: 137.425
A41: 2022 | B41: Jan | C41: 51.75 | E41: 625.715 | F41: 45.77
B42: Feb | D42: 55.89 | E42: 36.455
...

Sheet Country Bar Chart
A3: Country | B3: Sum of Sales
A4: United Kingdom | B4: 1173.92
A5: Ireland | B5: 3570.29
A6: United States | B6: 19041.355

Sheet Top 5 Customer
A3: Customer Name | B3: Sum of Sales
A4: Elysee Sketch | B4: 204.93
A5: Lacee Tanti | B5: 204.93
A6: Teddi Crowthe | B6: 204.93
A7: Nanny Lush | B7: 204.93
A8: Daniel Heinonen | B8: 204.93
A9: Shelli Keynd | B9: 204.93
A10: Alexa Sizey | B10: 218.73
A11: Allis Wilmore | B11: 237.82
A12: Brenn Dundredge | B12: 253.69

Sheet orders
A1: Order ID | B1: Order Date | C1: Customer ID | D1: Product ID | E1: Quantity | F1: Customer Name | G1: Email | H1: Country | I1: Coffee Type | J1: Roast Type | K1: Size | L1: Unit Price | M1: Sales | N1: CoffeeType Name | O1: Roast Type Name | P1: Loyalty Card
A2: QEV-37451-860 | B2: 43713 | C2: 17670-51384-MA | D2: R-M-1 | E2: 2 | F2: =_xlfn.XLOOKUP(C2,customers!$A$1:$A$1001,customers!$B$1:$B$1001,,0) -> Aloisia Allner | G2: {=IF(_xlfn.XLOOKUP(C2,customers!$A$1:$A$1001,customers!$C$1:$C$1001,_xleta.N/A,0)=0,"",_xlfn.XLOOKUP(C2,customers!$A$1:$A$1001,customers!$C$1:$C$1001,_xleta.N/A,0))} -> aallner0@lulu.com | H2: =_xlfn.XLOOKUP(C2,customers!$A$1:$A$1001,customers!$G$1:$G$1001,,0) -> United States | I2: =INDEX(products!$A$1:$G$49,MATCH(orders!$D2,products!$A$1:$A$49,0),MATCH(orders!I$1,products!$A$1:$G$1,0)) -> Rob | J2: =INDEX(products!$A$1:$G$49,MATCH(orders!$D2,products!$A$1:$A$49,0),MATCH(orders!J$1,products!$A$1:$G$1,0)) -> M | K2: =INDEX(products!$A$1:$G$49,MATCH(orders!$D2,products!$A$1:$A$49,0),MATCH(orders!K$1,products!$A$1:$G$1,0)) -> 1 | L2: =INDEX(products!$A$1:$G$49,MATCH(orders!$D2,products!$A$1:$A$49,0),MATCH(orders!L$1,products!$A$1:$G$1,0)) -> 9.95 | M2: =L2*E2 -> 19.9 | N2: =IF(I2="ROB","Robusta",IF(I2="EXC","Excelsa",IF(I2="Ara","Arabica",IF(I2="lib","Liberica","")))) -> Robusta | O2: =IF(J2="M","Medium",IF(J2="L","Large",IF(J2="D","Dark",""))) -> Medium | P2: =_xlfn.XLOOKUP(Table1[[#This Row],[Customer ID]],customers!$A$1:$A$1001,customers!$I$1:$I$1001,,0) -> Yes
A3: QEV-37451-860 | B3: 43713 | C3: 17670-51384-MA | D3: E-M-0.5 | E3: 5 | F3: =_xlfn.XLOOKUP(C3,customers!$A$1:$A$1001,customers!$B$1:$B$1001,,0) -> Aloisia Allner | G3: {=IF(_xlfn.XLOOKUP(C3,customers!$A$1:$A$1001,customers!$C$1:$C$1001,_xleta.N/A,0)=0,"",_xlfn.XLOOKUP(C3,customers!$A$1:$A$1001,customers!$C$1:$C$1001,_xleta.N/A,0))} -> aallner0@lulu.com | H3: =_xlfn.XLOOKUP(C3,customers!$A$1:$A$1001,customers!$G$1:$G$1001,,0) -> United States | I3: =INDEX(products!$A$1:$G$49,MATCH(orders!D3,products!$A$1:$A$49,0),MATCH(orders!$I$1,products!$A$1:$G$1,0)) -> Exc | J3: =INDEX(products!$A$1:$G$49,MATCH(orders!$D3,products!$A$1:$A$49,0),MATCH(orders!J$1,products!$A$1:$G$1,0)) -> M | K3: =INDEX(products!$A$1:$G$49,MATCH(orders!$D3,products!$A$1:$A$49,0),MATCH(orders!K$1,products!$A$1:$G$1,0)) -> 0.5 | L3: =INDEX(products!$A$1:$G$49,MATCH(orders!$D3,products!$A$1:$A$49,0),MATCH(orders!L$1,products!$A$1:$G$1,0)) -> 8.25 | M3: =L3*E3 -> 41.25 | N3: =IF(I3="ROB","Robusta",IF(I3="EXC","Excelsa",IF(I3="Ara","Arabica",IF(I3="lib","Liberica","")))) -> Excelsa | O3: =IF(J3="M","Medium",IF(J3="L","Large",IF(J3="D","Dark",""))) -> Medium | P3: =_xlfn.XLOOKUP(Table1[[#This Row],[Customer ID]],customers!$A$1:$A$1001,customers!$I$1:$I$1001,,0) -> Yes
A4: FAA-43335-268 | B4: 44364 | C4: 21125-22134-PX | D4: A-L-1 | E4: 1 | F4: =_xlfn.XLOOKUP(C4,customers!$A$1:$A$1001,customers!$B$1:$B$1001,,0) -> Jami Redholes | G4: {=IF(_xlfn.XLOOKUP(C4,customers!$A$1:$A$1001,customers!$C$1:$C$1001,_xleta.N/A,0)=0,"",_xlfn.XLOOKUP(C4,customers!$A$1:$A$1001,customers!$C$1:$C$1001,_xleta.N/A,0))} -> jredholes2@tmall.com | H4: =_xlfn.XLOOKUP(C4,customers!$A$1:$A$1001,customers!$G$1:$G$1001,,0) -> United States | I4: =INDEX(products!$A$1:$G$49,MATCH(orders!D4,products!$A$1:$A$49,0),MATCH(orders!$I$1,products!$A$1:$G$1,0)) -> Ara | J4: =INDEX(products!$A$1:$G$49,MATCH(orders!$D4,products!$A$1:$A$49,0),MATCH(orders!J$1,products!$A$1:$G$1,0)) -> L | K4: =INDEX(products!$A$1:$G$49,MATCH(orders!$D4,products!$A$1:$A$49,0),MATCH(orders!K$1,products!$A$1:$G$1,0)) -> 1 | L4: =INDEX(products!$A$1:$G$49,MATCH(orders!$D4,products!$A$1:$A$49,0),MATCH(orders!L$1,products!$A$1:$G$1,0)) -> 12.95 | M4: =L4*E4 -> 12.95 | N4: =IF(I4="ROB","Robusta",IF(I4="EXC","Excelsa",IF(I4="Ara","Arabica",IF(I4="lib","Liberica","")))) -> Arabica | O4: =IF(J4="M","Medium",IF(J4="L","Large",IF(J4="D","Dark",""))) -> Large | P4: =_xlfn.XLOOKUP(Table1[[#This Row],[Customer ID]],customers!$A$1:$A$1001,customers!$I$1:$I$1001,,0) -> Yes
A5: KAC-83089-793 | B5: 44392 | C5: 23806-46781-OU | D5: E-M-1 | E5: 2 | F5: =_xlfn.XLOOKUP(C5,customers!$A$1:$A$1001,customers!$B$1:$B$1001,,0) -> Christoffer O' Shea | G5: {=IF(_xlfn.XLOOKUP(C5,customers!$A$1:$A$1001,customers!$C$1:$C$1001,_xleta.N/A,0)=0,"",_xlfn.XLOOKUP(C5,customers!$A$1:$A$1001,customers!$C$1:$C$1001,_xleta.N/A,0))} | H5: =_xlfn.XLOOKUP(C5,customers!$A$1:$A$1001,customers!$G$1:$G$1001,,0) -> Ireland | I5: =INDEX(products!$A$1:$G$49,MATCH(orders!D5,products!$A$1:$A$49,0),MATCH(orders!$I$1,products!$A$1:$G$1,0)) -> Exc | J5: =INDEX(products!$A$1:$G$49,MATCH(orders!$D5,products!$A$1:$A$49,0),MATCH(orders!J$1,products!$A$1:$G$1,0)) -> M | K5: =INDEX(products!$A$1:$G$49,MATCH(orders!$D5,products!$A$1:$A$49,0),MATCH(orders!K$1,products!$A$1:$G$1,0)) -> 1 | L5: =INDEX(products!$A$1:$G$49,MATCH(orders!$D5,products!$A$1:$A$49,0),MATCH(orders!L$1,products!$A$1:$G$1,0)) -> 13.75 | M5: =L5*E5 -> 27.5 | N5: =IF(I5="ROB","Robusta",IF(I5="EXC","Excelsa",IF(I5="Ara","Arabica",IF(I5="lib","Liberica","")))) -> Excelsa | O5: =IF(J5="M","Medium",IF(J5="L","Large",IF(J5="D","Dark",""))) -> Medium | P5: =_xlfn.XLOOKUP(Table1[[#This Row],[Customer ID]],customers!$A$1:$A$1001,customers!$I$1:$I$1001,,0) -> No
A6: KAC-83089-793 | B6: 44392 | C6: 23806-46781-OU | D6: R-L-2.5 | E6: 2 | F6: =_xlfn.XLOOKUP(C6,customers!$A$1:$A$1001,customers!$B$1:$B$1001,,0) -> Christoffer O' Shea | G6: {=IF(_xlfn.XLOOKUP(C6,customers!$A$1:$A$1001,customers!$C$1:$C$1001,_xleta.N/A,0)=0,"",_xlfn.XLOOKUP(C6,customers!$A$1:$A$1001,customers!$C$1:$C$1001,_xleta.N/A,0))} | H6: =_xlfn.XLOOKUP(C6,customers!$A$1:$A$1001,customers!$G$1:$G$1001,,0) -> Ireland | I6: =INDEX(products!$A$1:$G$49,MATCH(orders!D6,products!$A$1:$A$49,0),MATCH(orders!$I$1,products!$A$1:$G$1,0)) -> Rob | J6: =INDEX(products!$A$1:$G$49,MATCH(orders!$D6,products!$A$1:$A$49,0),MATCH(orders!J$1,products!$A$1:$G$1,0)) -> L | K6: =INDEX(products!$A$1:$G$49,MATCH(orders!$D6,products!$A$1:$A$49,0),MATCH(orders!K$1,products!$A$1:$G$1,0)) -> 2.5 | L6: =INDEX(products!$A$1:$G$49,MATCH(orders!$D6,products!$A$1:$A$49,0),MATCH(orders!L$1,products!$A$1:$G$1,0)) -> 27.485 | M6: =L6*E6 -> 54.97 | N6: =IF(I6="ROB","Robusta",IF(I6="EXC","Excelsa",IF(I6="Ara","Arabica",IF(I6="lib","Liberica","")))) -> Robusta | O6: =IF(J6="M","Medium",IF(J6="L","Large",IF(J6="D","Dark",""))) -> Large | P6: =_xlfn.XLOOKUP(Table1[[#This Row],[Customer ID]],customers!$A$1:$A$1001,customers!$I$1:$I$1001,,0) -> No
A7: CVP-18956-553 | B7: 44412 | C7: 86561-91660-RB | D7: L-D-1 | E7: 3 | F7: =_xlfn.XLOOKUP(C7,customers!$A$1:$A$1001,customers!$B$1:$B$1001,,0) -> Beryle Cottier | G7: {=IF(_xlfn.XLOOKUP(C7,customers!$A$1:$A$1001,customers!$C$1:$C$1001,_xleta.N/A,0)=0,"",_xlfn.XLOOKUP(C7,customers!$A$1:$A$1001,customers!$C$1:$C$1001,_xleta.N/A,0))} | H7: =_xlfn.XLOOKUP(C7,customers!$A$1:$A$1001,customers!$G$1:$G$1001,,0) -> United States | I7: =INDEX(products!$A$1:$G$49,MATCH(orders!D7,products!$A$1:$A$49,0),MATCH(orders!$I$1,products!$A$1:$G$1,0)) -> Lib | J7: =INDEX(products!$A$1:$G$49,MATCH(orders!$D7,products!$A$1:$A$49,0),MATCH(orders!J$1,products!$A$1:$G$1,0)) -> D | K7: =INDEX(products!$A$1:$G$49,MATCH(orders!$D7,products!$A$1:$A$49,0),MATCH(orders!K$1,products!$A$1:$G$1,0)) -> 1 | L7: =INDEX(products!$A$1:$G$49,MATCH(orders!$D7,products!$A$1:$A$49,0),MATCH(orders!L$1,products!$A$1:$G$1,0)) -> 12.95 | M7: =L7*E7 -> 38.85 | N7: =IF(I7="ROB","Robusta",IF(I7="EXC","Excelsa",IF(I7="Ara","Arabica",IF(I7="lib","Liberica","")))) -> Liberica | O7: =IF(J7="M","Medium",IF(J7="L","Large",IF(J7="D","Dark",""))) -> Dark | P7: =_xlfn.XLOOKUP(Table1[[#This Row],[Customer ID]],customers!$A$1:$A$1001,customers!$I$1:$I$1001,,0) -> No
A8: IPP-31994-879 | B8: 44582 | C8: 65223-29612-CB | D8: E-D-0.5 | E8: 3 | F8: =_xlfn.XLOOKUP(C8,customers!$A$1:$A$1001,customers!$B$1:$B$1001,,0) -> Shaylynn Lobe | G8: {=IF(_xlfn.XLOOKUP(C8,customers!$A$1:$A$1001,customers!$C$1:$C$1001,_xleta.N/A,0)=0,"",_xlfn.XLOOKUP(C8,customers!$A$1:$A$1001,customers!$C$1:$C$1001,_xleta.N/A,0))} -> slobe6@nifty.com | H8: =_xlfn.XLOOKUP(C8,customers!$A$1:$A$1001,customers!$G$1:$G$1001,,0) -> United States | I8: =INDEX(products!$A$1:$G$49,MATCH(orders!D8,products!$A$1:$A$49,0),MATCH(orders!$I$1,products!$A$1:$G$1,0)) -> Exc | J8: =INDEX(products!$A$1:$G$49,MATCH(orders!$D8,products!$A$1:$A$49,0),MATCH(orders!J$1,products!$A$1:$G$1,0)) -> D | K8: =INDEX(products!$A$1:$G$49,MATCH(orders!$D8,products!$A$1:$A$49,0),MATCH(orders!K$1,products!$A$1:$G$1,0)) -> 0.5 | L8: =INDEX(products!$A$1:$G$49,MATCH(orders!$D8,products!$A$1:$A$49,0),MATCH(orders!L$1,products!$A$1:$G$1,0)) -> 7.29 | M8: =L8*E8 -> 21.87 | N8: =IF(I8="ROB","Robusta",IF(I8="EXC","Excelsa",IF(I8="Ara","Arabica",IF(I8="lib","Liberica","")))) -> Excelsa | O8: =IF(J8="M","Medium",IF(J8="L","Large",IF(J8="D","Dark",""))) -> Dark | P8: =_xlfn.XLOOKUP(Table1[[#This Row],[Customer ID]],customers!$A$1:$A$1001,customers!$I$1:$I$1001,,0) -> Yes
A9: SNZ-65340-705 | B9: 44701 | C9: 21134-81676-FR | D9: L-L-0.2 | E9: 1 | F9: =_xlfn.XLOOKUP(C9,customers!$A$1:$A$1001,customers!$B$1:$B$1001,,0) -> Melvin Wharfe | G9: {=IF(_xlfn.XLOOKUP(C9,customers!$A$1:$A$1001,customers!$C$1:$C$1001,_xleta.N/A,0)=0,"",_xlfn.XLOOKUP(C9,customers!$A$1:$A$1001,customers!$C$1:$C$1001,_xleta.N/A,0))} | H9: =_xlfn.XLOOKUP(C9,customers!$A$1:$A$1001,customers!$G$1:$G$1001,,0) -> Ireland | I9: =INDEX(products!$A$1:$G$49,MATCH(orders!D9,products!$A$1:$A$49,0),MATCH(orders!$I$1,products!$A$1:$G$1,0)) -> Lib | J9: =INDEX(products!$A$1:$G$49,MATCH(orders!$D9,products!$A$1:$A$49,0),MATCH(orders!J$1,products!$A$1:$G$1,0)) -> L | K9: =INDEX(products!$A$1:$G$49,MATCH(orders!$D9,products!$A$1:$A$49,0),MATCH(orders!K$1,products!$A$1:$G$1,0)) -> 0.2 | L9: =INDEX(products!$A$1:$G$49,MATCH(orders!$D9,products!$A$1:$A$49,0),MATCH(orders!L$1,products!$A$1:$G$1,0)) -> 4.755 | M9: =L9*E9 -> 4.755 | N9: =IF(I9="ROB","Robusta",IF(I9="EXC","Excelsa",IF(I9="Ara","Arabica",IF(I9="lib","Liberica","")))) -> Liberica | O9: =IF(J9="M","Medium",IF(J9="L","Large",IF(J9="D","Dark",""))) -> Large | P9: =_xlfn.XLOOKUP(Table1[[#This Row],[Customer ID]],customers!$A$1:$A$1001,customers!$I$1:$I$1001,,0) -> Yes
A10: EZT-46571-659 | B10: 43467 | C10: 03396-68805-ZC | D10: R-M-0.5 | E10: 3 | F10: =_xlfn.XLOOKUP(C10,customers!$A$1:$A$1001,customers!$B$1:$B$1001,,0) -> Guthrey Petracci | G10: {=IF(_xlfn.XLOOKUP(C10,customers!$A$1:$A$1001,customers!$C$1:$C$1001,_xleta.N/A,0)=0,"",_xlfn.XLOOKUP(C10,customers!$A$1:$A$1001,customers!$C$1:$C$1001,_xleta.N/A,0))} -> gpetracci8@livejournal.com | H10: =_xlfn.XLOOKUP(C10,customers!$A$1:$A$1001,customers!$G$1:$G$1001,,0) -> United States | I10: =INDEX(products!$A$1:$G$49,MATCH(orders!D10,products!$A$1:$A$49,0),MATCH(orders!$I$1,products!$A$1:$G$1,0)) -> Rob | J10: =INDEX(products!$A$1:$G$49,MATCH(orders!$D10,products!$A$1:$A$49,0),MATCH(orders!J$1,products!$A$1:$G$1,0)) -> M | K10: =INDEX(products!$A$1:$G$49,MATCH(orders!$D10,products!$A$1:$A$49,0),MATCH(orders!K$1,products!$A$1:$G$1,0)) -> 0.5 | L10: =INDEX(products!$A$1:$G$49,MATCH(orders!$D10,products!$A$1:$A$49,0),MATCH(orders!L$1,products!$A$1:$G$1,0)) -> 5.97 | M10: =L10*E10 -> 17.91 | N10: =IF(I10="ROB","Robusta",IF(I10="EXC","Excelsa",IF(I10="Ara","Arabica",IF(I10="lib","Liberica","")))) -> Robusta | O10: =IF(J10="M","Medium",IF(J10="L","Large",IF(J10="D","Dark",""))) -> Medium | P10: =_xlfn.XLOOKUP(Table1[[#This Row],[Customer ID]],customers!$A$1:$A$1001,customers!$I$1:$I$1001,,0) -> No
A11: NWQ-70061-912 | B11: 43713 | C11: 61021-27840-ZN | D11: R-M-0.5 | E11: 1 | F11: =_xlfn.XLOOKUP(C11,customers!$A$1:$A$1001,customers!$B$1:$B$1001,,0) -> Rodger Raven | G11: {=IF(_xlfn.XLOOKUP(C11,customers!$A$1:$A$1001,customers!$C$1:$C$1001,_xleta.N/A,0)=0,"",_xlfn.XLOOKUP(C11,customers!$A$1:$A$1001,customers!$C$1:$C$1001,_xleta.N/A,0))} -> rraven9@ed.gov | H11: =_xlfn.XLOOKUP(C11,customers!$A$1:$A$1001,customers!$G$1:$G$1001,,0) -> United States | I11: =INDEX(products!$A$1:$G$49,MATCH(orders!D11,products!$A$1:$A$49,0),MATCH(orders!$I$1,products!$A$1:$G$1,0)) -> Rob | J11: =INDEX(products!$A$1:$G$49,MATCH(orders!$D11,products!$A$1:$A$49,0),MATCH(orders!J$1,products!$A$1:$G$1,0)) -> M | K11: =INDEX(products!$A$1:$G$49,MATCH(orders!$D11,products!$A$1:$A$49,0),MATCH(orders!K$1,products!$A$1:$G$1,0)) -> 0.5 | L11: =INDEX(products!$A$1:$G$49,MATCH(orders!$D11,products!$A$1:$A$49,0),MATCH(orders!L$1,products!$A$1:$G$1,0)) -> 5.97 | M11: =L11*E11 -> 5.97 | N11: =IF(I11="ROB","Robusta",IF(I11="EXC","Excelsa",IF(I11="Ara","Arabica",IF(I11="lib","Liberica","")))) -> Robusta | O11: =IF(J11="M","Medium",IF(J11="L","Large",IF(J11="D","Dark",""))) -> Medium | P11: =_xlfn.XLOOKUP(Table1[[#This Row],[Customer ID]],customers!$A$1:$A$1001,customers!$I$1:$I$1001,,0) -> No
A12: BKK-47233-845 | B12: 44263 | C12: 76239-90137-UQ | D12: A-D-1 | E12: 4 | F12: =_xlfn.XLOOKUP(C12,customers!$A$1:$A$1001,customers!$B$1:$B$1001,,0) -> Ferrell Ferber | G12: {=IF(_xlfn.XLOOKUP(C12,customers!$A$1:$A$1001,customers!$C$1:$C$1001,_xleta.N/A,0)=0,"",_xlfn.XLOOKUP(C12,customers!$A$1:$A$1001,customers!$C$1:$C$1001,_xleta.N/A,0))} -> fferbera@businesswire.com | H12: =_xlfn.XLOOKUP(C12,customers!$A$1:$A$1001,customers!$G$1:$G$1001,,0) -> United States | I12: =INDEX(products!$A$1:$G$49,MATCH(orders!D12,products!$A$1:$A$49,0),MATCH(orders!$I$1,products!$A$1:$G$1,0)) -> Ara | J12: =INDEX(products!$A$1:$G$49,MATCH(orders!$D12,products!$A$1:$A$49,0),MATCH(orders!J$1,products!$A$1:$G$1,0)) -> D | K12: =INDEX(products!$A$1:$G$49,MATCH(orders!$D12,products!$A$1:$A$49,0),MATCH(orders!K$1,products!$A$1:$G$1,0)) -> 1 | L12: =INDEX(products!$A$1:$G$49,MATCH(orders!$D12,products!$A$1:$A$49,0),MATCH(orders!L$1,products!$A$1:$G$1,0)) -> 9.95 | M12: =L12*E12 -> 39.8 | N12: =IF(I12="ROB","Robusta",IF(I12="EXC","Excelsa",IF(I12="Ara","Arabica",IF(I12="lib","Liberica","")))) -> Arabica | O12: =IF(J12="M","Medium",IF(J12="L","Large",IF(J12="D","Dark",""))) -> Dark | P12: =_xlfn.XLOOKUP(Table1[[#This Row],[Customer ID]],customers!$A$1:$A$1001,customers!$I$1:$I$1001,,0) -> No
A13: VQR-01002-970 | B13: 44132 | C13: 49315-21985-BB | D13: E-L-2.5 | E13: 5 | F13: =_xlfn.XLOOKUP(C13,customers!$A$1:$A$1001,customers!$B$1:$B$1001,,0) -> Duky Phizackerly | G13: {=IF(_xlfn.XLOOKUP(C13,customers!$A$1:$A$1001,customers!$C$1:$C$1001,_xleta.N/A,0)=0,"",_xlfn.XLOOKUP(C13,customers!$A$1:$A$1001,customers!$C$1:$C$1001,_xleta.N/A,0))} -> dphizackerlyb@utexas.edu | H13: =_xlfn.XLOOKUP(C13,customers!$A$1:$A$1001,customers!$G$1:$G$1001,,0) -> United States | I13: =INDEX(products!$A$1:$G$49,MATCH(orders!D13,products!$A$1:$A$49,0),MATCH(orders!$I$1,products!$A$1:$G$1,0)) -> Exc | J13: =INDEX(products!$A$1:$G$49,MATCH(orders!$D13,products!$A$1:$A$49,0),MATCH(orders!J$1,products!$A$1:$G$1,0)) -> L | K13: =INDEX(products!$A$1:$G$49,MATCH(orders!$D13,products!$A$1:$A$49,0),MATCH(orders!K$1,products!$A$1:$G$1,0)) -> 2.5 | L13: =INDEX(products!$A$1:$G$49,MATCH(orders!$D13,products!$A$1:$A$49,0),MATCH(orders!L$1,products!$A$1:$G$1,0)) -> 34.155 | M13: =L13*E13 -> 170.775 | N13: =IF(I13="ROB","Robusta",IF(I13="EXC","Excelsa",IF(I13="Ara","Arabica",IF(I13="lib","Liberica","")))) -> Excelsa | O13: =IF(J13="M","Medium",IF(J13="L","Large",IF(J13="D","Dark",""))) -> Large | P13: =_xlfn.XLOOKUP(Table1[[#This Row],[Customer ID]],customers!$A$1:$A$1001,customers!$I$1:$I$1001,,0) -> Yes
A14: SZW-48378-399 | B14: 44744 | C14: 34136-36674-OM | D14: R-M-1 | E14: 5 | F14: =_xlfn.XLOOKUP(C14,customers!$A$1:$A$1001,customers!$B$1:$B$1001,,0) -> Rosaleen Scholar | G14: {=IF(_xlfn.XLOOKUP(C14,customers!$A$1:$A$1001,customers!$C$1:$C$1001,_xleta.N/A,0)=0,"",_xlfn.XLOOKUP(C14,customers!$A$1:$A$1001,customers!$C$1:$C$1001,_xleta.N/A,0))} -> rscholarc@nyu.edu | H14: =_xlfn.XLOOKUP(C14,customers!$A$1:$A$1001,customers!$G$1:$G$1001,,0) -> United States | I14: =INDEX(products!$A$1:$G$49,MATCH(orders!D14,products!$A$1:$A$49,0),MATCH(orders!$I$1,products!$A$1:$G$1,0)) -> Rob | J14: =INDEX(products!$A$1:$G$49,MATCH(orders!$D14,products!$A$1:$A$49,0),MATCH(orders!J$1,products!$A$1:$G$1,0)) -> M | K14: =INDEX(products!$A$1:$G$49,MATCH(orders!$D14,products!$A$1:$A$49,0),MATCH(orders!K$1,products!$A$1:$G$1,0)) -> 1 | L14: =INDEX(products!$A$1:$G$49,MATCH(orders!$D14,products!$A$1:$A$49,0),MATCH(orders!L$1,products!$A$1:$G$1,0)) -> 9.95 | M14: =L14*E14 -> 49.75 | N14: =IF(I14="ROB","Robusta",IF(I14="EXC","Excelsa",IF(I14="Ara","Arabica",IF(I14="lib","Liberica","")))) -> Robusta | O14: =IF(J14="M","Medium",IF(J14="L","Large",IF(J14="D","Dark",""))) -> Medium | P14: =_xlfn.XLOOKUP(Table1[[#This Row],[Customer ID]],customers!$A$1:$A$1001,customers!$I$1:$I$1001,,0) -> No
... A1001: IRV-20769-219 | B1001: 44119 | C1001: 77131-58092-GE | D1001: E-M-0.2 | E1001: 3 | F1001: =_xlfn.XLOOKUP(C1001,customers!$A$1:$A$1001,customers!$B$1:$B$1001,,0) -> Vidovic Antonelli | G1001: {=IF(_xlfn.XLOOKUP(C1001,customers!$A$1:$A$1001,customers!$C$1:$C$1001,_xleta.N/A,0)=0,"",_xlfn.XLOOKUP(C1001,customers!$A$1:$A$1001,customers!$C$1:$C$1001,_xleta.N/A,0))} | H1001: =_xlfn.XLOOKUP(C1001,customers!$A$1:$A$1001,customers!$G$1:$G$1001,,0) -> United Kingdom | I1001: =INDEX(products!$A$1:$G$49,MATCH(orders!D1001,products!$A$1:$A$49,0),MATCH(orders!$I$1,products!$A$1:$G$1,0)) -> Exc | J1001: =INDEX(products!$A$1:$G$49,MATCH(orders!$D1001,products!$A$1:$A$49,0),MATCH(orders!J$1,products!$A$1:$G$1,0)) -> M | K1001: =INDEX(products!$A$1:$G$49,MATCH(orders!$D1001,products!$A$1:$A$49,0),MATCH(orders!K$1,products!$A$1:$G$1,0)) -> 0.2 | L1001: =INDEX(products!$A$1:$G$49,MATCH(orders!$D1001,products!$A$1:$A$49,0),MATCH(orders!L$1,products!$A$1:$G$1,0)) -> 4.125 | M1001: =L1001*E1001 -> 12.375 | N1001: =IF(I1001="ROB","Robusta",IF(I1001="EXC","Excelsa",IF(I1001="Ara","Arabica",IF(I1001="lib","Liberica","")))) -> Excelsa | O1001: =IF(J1001="M","Medium",IF(J1001="L","Large",IF(J1001="D","Dark",""))) -> Medium | P1001: =_xlfn.XLOOKUP(Table1[[#This Row],[Customer ID]],customers!$A$1:$A$1001,customers!$I$1:$I$1001,,0) -> Yes

Sheet customers
A1: Customer ID | B1: Customer Name | C1: Email | D1: Phone Number | E1: Address Line 1 | F1: City | G1: Country | H1: Postcode | I1: Loyalty Card
A2: 17670-51384-MA | B2: Aloisia Allner | C2: aallner0@lulu.com | D2: +1 (862) 817-0124 | E2: 57999 Pepper Wood Alley | F2: Paterson | G2: United States | H2: 7505 | I2: Yes
A3: 73342-18763-UW | B3: Piotr Bote | C3: pbote1@yelp.com | D3: +353 (913) 396-4653 | E3: 2112 Ridgeway Hill | F3: Crumlin | G3: Ireland | H3: D6W | I3: No
A4: 21125-22134-PX | B4: Jami Redholes | C4: jredholes2@tmall.com | D4: +1 (210) 986-6806 | E4: 5214 Bartillon Park | F4: San Antonio | G4: United States | H4: 78205 | I4: Yes
A5: 71253-00052-RN | B5: Dene Azema | C5: dazema3@facebook.com | D5: +1 (217) 418-0714 | E5: 27 Maywood Place | F5: Springfield | G5: United States | H5: 62711 | I5: Yes
A6: 23806-46781-OU | B6: Christoffer O' Shea | D6: +353 (698) 362-9201 | E6: 38980 Manitowish Junction | F6: Cill Airne | G6: Ireland | H6: N41 | I6: No
A7: 86561-91660-RB | B7: Beryle Cottier | D7: +1 (570) 289-7473 | E7: 2651 Stoughton Place | F7: Scranton | G7: United States | H7: 18505 | I7: No
A8: 65223-29612-CB | B8: Shaylynn Lobe | C8: slobe6@nifty.com | D8: +1 (937) 954-4541 | E8: 7005 Mariners Cove Place | F8: Dayton | G8: United States | H8: 45440 | I8: Yes
A9: 21134-81676-FR | B9: Melvin Wharfe | D9: +353 (507) 574-3034 | E9: 7 Straubel Road | F9: Kill | G9: Ireland | H9: P24 | I9: Yes
A10: 03396-68805-ZC | B10: Guthrey Petracci | C10: gpetracci8@livejournal.com | D10: +1 (310) 868-1842 | E10: 949 Paget Parkway | F10: Los Angeles | G10: United States | H10: 90045 | I10: No
A11: 61021-27840-ZN | B11: Rodger Raven | C11: rraven9@ed.gov | D11: +1 (213) 263-0288 | E11: 1 Reinke Avenue | F11: Los Angeles | G11: United States | H11: 90065 | I11: No
A12: 76239-90137-UQ | B12: Ferrell Ferber | C12: fferbera@businesswire.com | D12: +1 (408) 383-5302 | E12: 68 High Crossing Court | F12: San Jose | G12: United States | H12: 95160 | I12: No
A13: 49315-21985-BB | B13: Duky Phizackerly | C13: dphizackerlyb@utexas.edu | D13: +1 (408) 533-6012 | E13: 28643 Bluejay Crossing | F13: San Jose | G13: United States | H13: 95194 | I13: Yes
A14: 34136-36674-OM | B14: Rosaleen Scholar | C14: rscholarc@nyu.edu | D14: +1 (804) 420-0420 | E14: 80915 Montana Park | F14: Richmond | G14: United States | H14: 23285 | I14: No
A15: 39396-12890-PE | B15: Terence Vanyutin | C15: tvanyutind@wix.com | E15: 331 Bunting Hill | F15: Migrate | G15: United States | H15: 41905 | I15: No
A16: 95875-73336-RG | B16: Patrice Trobe | C16: ptrobee@wunderground.com | D16: +1 (314) 240-7896 | E16: 827 Declaration Plaza | F16: Saint Louis | G16: United States | H16: 63131 | I16: Yes
A17: 25473-43727-BY | B17: Llywellyn Oscroft | C17: loscroftf@ebay.co.uk | E17: 022 Roth Place | F17: Philadelphia | G17: United States | H17: 19172 | I17: No
A18: 99643-51048-IQ | B18: Minni Alabaster | C18: malabasterg@hexun.com | D18: +1 (971) 483-6255 | E18: 3 Charing Cross Trail | F18: Portland | G18: United States | H18: 97271 | I18: No
A19: 62173-15287-CU | B19: Rhianon Broxup | C19: rbroxuph@jimdo.com | D19: +1 (713) 663-1338 | E19: 83517 Thierer Court | F19: Houston | G19: United States | H19: 77240 | I19: No
A20: 57611-05522-ST | B20: Pall Redford | C20: predfordi@ow.ly | E20: 7337 Hayes Junction | F20: Caherconlish | G20: Ireland | H20: F45 | I20: Yes
A21: 76664-37050-DT | B21: Aurea Corradino | C21: acorradinoj@harvard.edu | D21: +1 (646) 202-5965 | E21: 698 Canary Terrace | F21: New York City | G21: United States | H21: 10060 | I21: Yes
A22: 84565-53984-SX | B22: Kendal Scardefield | D22: +353 (733) 405-3302 | E22: 3 Northridge Crossing | F22: Clondalkin | G22: Ireland | H22: D24 | I22: Yes
A23: 03090-88267-BQ | B23: Avrit Davidowsky | C23: adavidowskyl@netvibes.com | D23: +1 (616) 481-9962 | E23: 9 Warrior Junction | F23: Grand Rapids | G23: United States | H23: 49560 | I23: No
A24: 37651-47492-NC | B24: Annabel Antuk | C24: aantukm@kickstarter.com | D24: +1 (941) 740-6268 | E24: 77965 Lawn Park | F24: Punta Gorda | G24: United States | H24: 33982 | I24: Yes
A25: 95399-57205-HI | B25: Iorgo Kleinert | C25: ikleinertn@timesonline.co.uk | D25: +1 (360) 352-6598 | E25: 1 Morningstar Lane | F25: Vancouver | G25: United States | H25: 98682 | I25: Yes
A26: 24010-66714-HW | B26: Chrisy Blofeld | C26: cblofeldo@amazon.co.uk | D26: +1 (303) 936-3357 | E26: 013 Talisman Terrace | F26: Englewood | G26: United States | H26: 80150 | I26: No
A27: 07591-92789-UA | B27: Culley Farris | D27: +1 (941) 267-4822 | E27: 4 Mitchell Drive | F27: Punta Gorda | G27: United States | H27: 33982 | I27: Yes
A28: 49231-44455-IC | B28: Selene Shales | C28: sshalesq@umich.edu | D28: +1 (707) 881-5004 | E28: 74 Bultman Plaza | F28: Petaluma | G28: United States | H28: 94975 | I28: Yes
A29: 50124-88608-EO | B29: Vivie Danneil | C29: vdanneilr@mtv.com | D29: +353 (751) 346-0399 | E29: 5626 Darwin Avenue | F29: Tralee | G29: Ireland | H29: V92 | I29: No
A30: 00888-74814-UZ | B30: Theresita Newbury | C30: tnewburys@usda.gov | D30: +353 (803) 587-0026 | E30: 79526 Bultman Lane | F30: Clonskeagh | G30: Ireland | H30: D04 | I30: No
A31: 14158-30713-OB | B31: Mozelle Calcutt | C31: mcalcuttt@baidu.com | D31: +353 (928) 869-1762 | E31: 4389 Russell Way | F31: Rathwire | G31: Ireland | H31: Y25 | I31: Yes
A32: 51427-89175-QJ | B32: Adrian Swaine | D32: +1 (303) 486-9517 | E32: 95 Straubel Hill | F32: Aurora | G32: United States | H32: 80044 | I32: No
A33: 52082-49024-ON | B33: Ray Leivesley | C33: rleivesleyv@canalblog.com | D33: +1 (212) 535-7791 | E33: 91 Stephen Drive | F33: Jamaica | G33: United States | H33: 11407 | I33: No
A34: 04540-43685-DV | B34: Nelly Basezzi | C34: nbasezziw@webeden.co.uk | D34: +353 (125) 815-7345 | E34: 923 Mallard Junction | F34: Bailieborough | G34: Ireland | H34: C15 | I34: Yes
A35: 39123-12846-YJ | B35: Gallard Gatheral | C35: ggatheralx@123-reg.co.uk | E35: 40 Clemons Place | F35: Grand Forks | G35: United States | H35: 58207 | I35: No
A36: 44981-99666-XB | B36: Una Welberry | C36: uwelberryy@ebay.co.uk | D36: +44 (392) 503-8132 | E36: 40915 Schlimgen Park | F36: Upton | G36: United Kingdom | H36: DN21 | I36: Yes
A37: 24825-51803-CQ | B37: Faber Eilhart | C37: feilhartz@who.int | D37: +1 (304) 510-6095 | E37: 6966 Victoria Street | F37: Charleston | G37: United States | H37: 25362 | I37: No
A38: 77634-13918-GJ | B38: Zorina Ponting | C38: zponting10@altervista.org | D38: +1 (501) 172-1476 | E38: 7118 Holmberg Court | F38: Little Rock | G38: United States | H38: 72204 | I38: No
A39: 13694-25001-LX | B39: Silvio Strase | C39: sstrase11@booking.com | D39: +1 (303) 579-8015 | E39: 5 Forest Lane | F39: Denver | G39: United States | H39: 80291 | I39: No
A40: 08523-01791-TI | B40: Dorie de la Tremoille | C40: dde12@unesco.org | D40: +1 (612) 492-5160 | E40: 0817 Dennis Street | F40: Minneapolis | G40: United States | H40: 55458 | I40: No
...

Sheet products
A1: Product ID | B1: Coffee Type | C1: Roast Type | D1: Size | E1: Unit Price | F1: Price per 100g | G1: Profit
A2: A-L-0.2 | B2: Ara | C2: L | D2: 0.2 | E2: 3.885 | F2: 1.9425 | G2: 0.34965
A3: A-L-0.5 | B3: Ara | C3: L | D3: 0.5 | E3: 7.77 | F3: 1.554 | G3: 0.6993
A4: A-L-1 | B4: Ara | C4: L | D4: 1 | E4: 12.95 | F4: 1.295 | G4: 1.1655
A5: A-L-2.5 | B5: Ara | C5: L | D5: 2.5 | E5: 29.785 | F5: 1.1914 | G5: 2.68065
A6: A-M-0.2 | B6: Ara | C6: M | D6: 0.2 | E6: 3.375 | F6: 1.6875 | G6: 0.30375
A7: A-M-0.5 | B7: Ara | C7: M | D7: 0.5 | E7: 6.75 | F7: 1.35 | G7: 0.6075
A8: A-M-1 | B8: Ara | C8: M | D8: 1 | E8: 11.25 | F8: 1.125 | G8: 1.0125
A9: A-M-2.5 | B9: Ara | C9: M | D9: 2.5 | E9: 25.875 | F9: 1.035 | G9: 2.32875
A10: A-D-0.2 | B10: Ara | C10: D | D10: 0.2 | E10: 2.985 | F10: 1.4925 | G10: 0.26865
A11: A-D-0.5 | B11: Ara | C11: D | D11: 0.5 | E11: 5.97 | F11: 1.194 | G11: 0.5373
A12: A-D-1 | B12: Ara | C12: D | D12: 1 | E12: 9.95 | F12: 0.995 | G12: 0.8955
A13: A-D-2.5 | B13: Ara | C13: D | D13: 2.5 | E13: 22.885 | F13: 0.9154 | G13: 2.05965
... A49: E-D-2.5 | B49: Exc | C49: D | D49: 2.5 | E49: 27.945 | F49: 1.1178 | G49: 3.07395
